<?xml version="1.0"?>
<sdf version="1.7">
    <model name="velodyne_hdl-32">
        <link name="base">
            <pose>0 0 0.029335 0 0 0</pose>
            <inertial>
                <mass>1.2</mass>
                <inertia>
                    <ixx>0.001087473</ixx>
                    <iyy>0.001087473</iyy>
                    <izz>0.001092437</izz>
                    <ixy>0</ixy>
                    <ixz>0</ixz>
                    <iyz>0</iyz>
                </inertia>
            </inertial>
            <collision name="base_collision">
                <geometry>
                    <cylinder>
                        <radius>.04267</radius>
                        <length>.05867</length>
                    </cylinder>
                </geometry>
            </collision>
            <visual name="base_visual">
                <geometry>
                    <cylinder>
                        <radius>.04267</radius>
                        <length>.05867</length>
                    </cylinder>
                </geometry>
            </visual>
        </link>

        <link name="top">

            <pose>0 0 0.095455 0 0 0</pose>
            <inertial>
                <mass>0.1</mass>
                <inertia>
                    <ixx>0.000090623</ixx>
                    <iyy>0.000090623</iyy>
                    <izz>0.000091036</izz>
                    <ixy>0</ixy>
                    <ixz>0</ixz>
                    <iyz>0</iyz>
                </inertia>
            </inertial>
            <collision name="top_collision">
                <geometry>
                    <cylinder>
                        <radius>0.04267</radius>
                        <length>0.07357</length>
                    </cylinder>
                </geometry>
            </collision>

            <visual name="top_visual">
                <geometry>
                    <cylinder>
                        <radius>0.04267</radius>
                        <length>0.07357</length>
                    </cylinder>
                </geometry>
            </visual>

            <frame name="lidar_frame" attached_to='velodyne_hdl-32'>
                <pose>0 0 -0.004645 1.5707 0 0</pose>
            </frame>

            <sensor name='gpu_lidar' type='gpu_lidar'>

                <pose relative_to='lidar_frame'>0 0 0 0 0 0</pose>
                <topic>lidar</topic>
                <update_rate>10</update_rate>

                <ray>
                    <scan>
                        <horizontal>
                            <samples>1080</samples>
                            <resolution>1</resolution>
                            <min_angle>-1.57079633</min_angle>
                            <max_angle>1.57079633</max_angle>
                        </horizontal>
                        <vertical>
                            <samples>1</samples>
                            <resolution>0.01</resolution>
                            <min_angle>0</min_angle>
                            <max_angle>0</max_angle>
                        </vertical>
                    </scan>
                    <range>
                        <min>0.08</min>
                        <max>10.0</max>
                        <resolution>0.01</resolution>
                    </range>
                </ray>

                <always_on>1</always_on>
                <visualize>true</visualize>

            </sensor>

        </link>

        <joint type="revolute" name="joint">

            <pose>0 0 -0.036785 0 0 0</pose>

            <parent>base</parent>

            <child>top</child>

            <axis>

                <xyz>0 0 1</xyz>

                <limit>

                    <lower>-10000000000000000</lower>
                    <upper>10000000000000000</upper>
                </limit>
            </axis>
        </joint>
    </model>
</sdf>